Workbook

Sheet Assumptions
A1: Chagee Singapore · AI proposals 1-3 · model assumptions
A2: All money in Singapore dollars (S$). Illustrative assumptions, not Chagee data. Blue cells are inputs: change them and the Model and Cost plan sheets update. Base figures reuse the inputs behind the deck's earlier slides.
A4: Base business (from the deck) | B4: Value | C4: Unit | D4: Source / rationale
A5: Chagee outlets in Singapore | B5: 44 | C5: outlets | D5: L-sg-directory. Store count used on the storyboard deck. The doc also cites 46 (VnExpress, earlier); the later directory count is used.
A6: Cups per outlet per year (stabilised) | B6: 240000 | C6: cups | D6: Team-provided: a stabilised Chagee outlet in Singapore averages about 230,000 to 250,000+ cups a year; midpoint used.
A7: Average price per cup | B7: 5.9 | C7: S$ per cup | D7: Deck assumption (price per cup), illustrative.
A8: Gross margin | B8: 0.54 | C8: share of revenue | D8: Chagee's reported corporate gross margin, about 54% (figure provided by the team; check against Chagee's latest annual report before submission).
A9: Organic growth in cups per outlet | B9: 0.03 | C9: per year | D9: Illustrative same-store growth in cups, without the proposals. Applied to existing and new outlets.
A10: Labour cost per hour | B10: 15.06 | C10: S$ per hour | D10: Deck assumption (costs.labour_cost_per_hour), illustrative.
A11: Wage inflation | B11: 0.03 | C11: per year | D11: Illustrative wage inflation, applied to outlet staff costs and to the value of staff hours saved. Rent held flat.
A12: Tea machine cost per unit per month | B12: 1908.75 | C12: S$ per month | D12: Deck assumption (costs.machine_cost_per_unit_per_month), illustrative.
A14: Singapore operations (SG forecast sheet only) | B14: Value | C14: Unit | D14: Source / rationale
A15: Staff on shift, average | B15: 3 | C15: staff | D15: Illustrative. More at the peak, fewer when quiet. Used only for the Singapore forecast's labour line.
A16: Open hours per day | B16: 12 | C16: hours | D16: Deck assumption (store.open_hours_per_day), illustrative.
A17: Open days per year | B17: 360 | C17: days | D17: Deck assumption (store.open_days_per_year), illustrative.
A18: Rent per outlet | B18: 15000 | C18: S$ per month | D18: Deck assumption (site_ext.rent_per_month), illustrative.
A19: Utilities per outlet | B19: 2500 | C19: S$ per month | D19: Deck assumption (site_ext.utilities_per_month), illustrative.
A20: Cups sold through delivery apps | B20: 0.3 | C20: share of baseline cups | D20: Deck assumption (site_ext.delivery_share_of_cups), illustrative.
A21: Delivery-app commission | B21: 0.3 | C21: share of delivery sales | D21: Deck assumption (site_ext.delivery_commission_share). Charged on baseline sales; the proposals' extra cups are mostly in-store and app pickups.
A23: Proposal 1 · dynamic demand management | B23: Value | C23: Unit | D23: Source / rationale
A24: Cups lost at peak today | B24: 0.03 | C24: share of cups lost at peak (walk-aways, crowding) | D24: Illustrative. Cups customers would have bought but did not, because of queues.
A25: Share of lost cups recovered | B25: 0.3 | C25: share of lost cups recovered by redirection | D25: Illustrative. Customers who switch outlet or delivery channel instead of leaving.
A26: Orders redirected to another outlet | B26: 0.02 | C26: share of all orders redirected to another outlet | D26: Illustrative. Perks go to every redirected order, not only to customers who would otherwise have walked away, so redirected orders exceed recovered cups.
A27: Redirected orders given a switch perk | B27: 0.5 | C27: share of redirected orders given a switch perk | D27: Illustrative. Perks only while an outlet is swamped; some customers switch without one.
A28: Cost per switch perk | B28: 0.5 | C28: S$ per perk | D28: Illustrative average cost of a voucher or carrier bag.
A30: Proposal 2 · AI-enabled in-store planning | B30: Value | C30: Unit | D30: Source / rationale
A31: Extra cups served at the peak | B31: 0.005 | C31: share of cups added at the peak | D31: Illustrative. Staff and machines ready for busy days.
A32: Idle staff hours avoided | B32: 10 | C32: hours per outlet per week | D32: Illustrative. Rosters flex down on quiet days.
A33: Fresh stock wasted today | B33: 0.03 | C33: fresh stock written off, share of revenue | D33: Illustrative. Perishables prepped but not sold.
A34: Share of that waste avoided | B34: 0.2 | C34: share of that waste avoided | D34: Illustrative. Fresh prep matched to each week's demand.
A35: Net machines avoided per outlet | B35: 0.1 | C35: units per outlet | D35: Illustrative. Some outlets run one fewer, a few add one; the net is small.
A37: Proposal 3 · new-store site model | B37: Value | C37: Unit | D37: Source / rationale
A38: Extra cups at an AI-chosen site | B38: 0.1 | C38: extra net-new cups at an AI-chosen site vs a conventional pick | D38: Illustrative. Only the uplift is attributed to the site model, not the new outlet's whole revenue.
A40: Costs of the initiatives | B40: Value | C40: Unit | D40: Source / rationale
A41: Project manager | B41: 12000 | C41: S$ per month | D41: Illustrative project manager cost.
A42: AI engineer | B42: 14000 | C42: S$ per month | D42: Illustrative AI engineer cost.
A43: Platform build (one-off) | B43: 100000 | C43: S$ | D43: Illustrative, lean set-up: the dashboard and assistant run on off-the-shelf BI and AI services, configured rather than custom-built; external developers only add the app pop-up and the delivery-app link. Forecasts and the site model are built by our AI engineer, already costed in the project team.
A44: Data pipelines and cloud set-up (one-off) | B44: 60000 | C44: S$ | D44: Illustrative. Connecting the POS, app, delivery and stock data to one cloud warehouse, using standard connectors.
A45: Security and PDPA review (one-off) | B45: 20000 | C45: S$ | D45: Illustrative. Security testing and a PDPA review before customer data drives app pop-ups.
A46: Training per outlet (one-off) | B46: 0 | C46: S$ per outlet | D46: Cross-training is delivered by existing zone and store managers during normal shifts: no incremental cost.
...

Sheet Model
A1: Chagee Singapore · AI proposals 1-3 · five-year financial impact (S$)
A2: Incremental to Chagee Singapore without the proposals (organic growth and new outlets included in the baseline). Illustrative assumptions, not Chagee data. Execution starts January 2027; the project team is set up in late 2026.
A4: S$ | B4: 2026 | C4: 2027 | D4: 2028 | E4: 2029 | F4: 2030 | G4: 5-year total | H4: Assumptions
A6: Baseline · Chagee Singapore without the proposals
A7: Organic growth index | B7: =(1+Assumptions!$B$9)^(VALUE(B$4)-VALUE($B$4)) | C7: =(1+Assumptions!$B$9)^(VALUE(C$4)-VALUE($B$4)) | D7: =(1+Assumptions!$B$9)^(VALUE(D$4)-VALUE($B$4)) | E7: =(1+Assumptions!$B$9)^(VALUE(E$4)-VALUE($B$4)) | F7: =(1+Assumptions!$B$9)^(VALUE(F$4)-VALUE($B$4)) | H7: cups per outlet grow each year
A8: Wage index | B8: =(1+Assumptions!$B$11)^(VALUE(B$4)-VALUE($B$4)) | C8: =(1+Assumptions!$B$11)^(VALUE(C$4)-VALUE($B$4)) | D8: =(1+Assumptions!$B$11)^(VALUE(D$4)-VALUE($B$4)) | E8: =(1+Assumptions!$B$11)^(VALUE(E$4)-VALUE($B$4)) | F8: =(1+Assumptions!$B$11)^(VALUE(F$4)-VALUE($B$4)) | H8: wage inflation; rent held flat
A9: New outlets open (outlet-years) | B9: =SUM(Assumptions!$B$55:B$55)-Assumptions!B$55/2 | C9: =SUM(Assumptions!$B$55:C$55)-Assumptions!C$55/2 | D9: =SUM(Assumptions!$B$55:D$55)-Assumptions!D$55/2 | E9: =SUM(Assumptions!$B$55:E$55)-Assumptions!E$55/2 | F9: =SUM(Assumptions!$B$55:F$55)-Assumptions!F$55/2 | H9: outlets opened mid-year count as half a year
A10: Outlets open (average in the year) | B10: =Assumptions!$B$5+B9 | C10: =Assumptions!$B$5+C9 | D10: =Assumptions!$B$5+D9 | E10: =Assumptions!$B$5+E9 | F10: =Assumptions!$B$5+F9 | H10: today's outlets + new outlets
A11: Cups sold, all outlets | B11: =B10*Assumptions!$B$6*B7 | C11: =C10*Assumptions!$B$6*C7 | D11: =D10*Assumptions!$B$6*D7 | E11: =E10*Assumptions!$B$6*E7 | F11: =F10*Assumptions!$B$6*F7 | G11: =SUM(B11:F11) | H11: outlets × cups per outlet × growth
A12: Revenue, all outlets | B12: =B11*Assumptions!$B$7 | C12: =C11*Assumptions!$B$7 | D12: =D11*Assumptions!$B$7 | E12: =E11*Assumptions!$B$7 | F12: =F11*Assumptions!$B$7 | G12: =SUM(B12:F12) | H12: cups × price per cup
A14: Revenue impact · more cups captured and served
A15: Proposal 1 · cups recovered from walk-aways | B15: =B11*Assumptions!$B$24*Assumptions!$B$25*Assumptions!B$52*Assumptions!B$54 | C15: =C11*Assumptions!$B$24*Assumptions!$B$25*Assumptions!C$52*Assumptions!C$54 | D15: =D11*Assumptions!$B$24*Assumptions!$B$25*Assumptions!D$52*Assumptions!D$54 | E15: =E11*Assumptions!$B$24*Assumptions!$B$25*Assumptions!E$52*Assumptions!E$54 | F15: =F11*Assumptions!$B$24*Assumptions!$B$25*Assumptions!F$52*Assumptions!F$54 | G15: =SUM(B15:F15) | H15: cups lost at peak × share recovered × coverage × effectiveness
A16: Proposal 2 · extra cups served at the peak | B16: =B11*Assumptions!$B$31*Assumptions!B$53*Assumptions!B$54 | C16: =C11*Assumptions!$B$31*Assumptions!C$53*Assumptions!C$54 | D16: =D11*Assumptions!$B$31*Assumptions!D$53*Assumptions!D$54 | E16: =E11*Assumptions!$B$31*Assumptions!E$53*Assumptions!E$54 | F16: =F11*Assumptions!$B$31*Assumptions!F$53*Assumptions!F$54 | G16: =SUM(B16:F16) | H16: staff and machines ready for busy days
A17: Proposal 3 · extra cups at better-chosen sites | B17: =Assumptions!$B$6*Assumptions!$B$38*B9*B7 | C17: =Assumptions!$B$6*Assumptions!$B$38*C9*C7 | D17: =Assumptions!$B$6*Assumptions!$B$38*D9*D7 | E17: =Assumptions!$B$6*Assumptions!$B$38*E9*E7 | F17: =Assumptions!$B$6*Assumptions!$B$38*F9*F7 | G17: =SUM(B17:F17) | H17: new outlets × uplift vs a conventional site pick
A18: Additional cups sold | B18: =SUM(B15:B16)+B17 | C18: =SUM(C15:C16)+C17 | D18: =SUM(D15:D16)+D17 | E18: =SUM(E15:E16)+E17 | F18: =SUM(F15:F16)+F17 | G18: =SUM(B18:F18)
A20: Proposal 1 revenue | B20: =B15*Assumptions!$B$7 | C20: =C15*Assumptions!$B$7 | D20: =D15*Assumptions!$B$7 | E20: =E15*Assumptions!$B$7 | F20: =F15*Assumptions!$B$7 | G20: =SUM(B20:F20) | H20: cups × price per cup
A21: Proposal 2 revenue | B21: =B16*Assumptions!$B$7 | C21: =C16*Assumptions!$B$7 | D21: =D16*Assumptions!$B$7 | E21: =E16*Assumptions!$B$7 | F21: =F16*Assumptions!$B$7 | G21: =SUM(B21:F21) | H21: cups × price per cup
A22: Proposal 3 revenue | B22: =B17*Assumptions!$B$7 | C22: =C17*Assumptions!$B$7 | D22: =D17*Assumptions!$B$7 | E22: =E17*Assumptions!$B$7 | F22: =F17*Assumptions!$B$7 | G22: =SUM(B22:F22) | H22: cups × price per cup
A23: Additional revenue | B23: =SUM(B20:B22) | C23: =SUM(C20:C22) | D23: =SUM(D20:D22) | E23: =SUM(E20:E22) | F23: =SUM(F20:F22) | G23: =SUM(B23:F23)
A24: Less ingredients and packaging | B24: =-B23*(1-Assumptions!$B$8) | C24: =-C23*(1-Assumptions!$B$8) | D24: =-D23*(1-Assumptions!$B$8) | E24: =-E23*(1-Assumptions!$B$8) | F24: =-F23*(1-Assumptions!$B$8) | G24: =SUM(B24:F24) | H24: revenue × (1 − gross margin)
A25: Gross profit from additional sales | B25: =B23+B24 | C25: =C23+C24 | D25: =D23+D24 | E25: =E23+E24 | F25: =F23+F24 | G25: =SUM(B25:F25)
A27: Cost impact · leaner operations (Proposal 2)
A28: Idle staff hours avoided | B28: =Assumptions!$B$32*52*B10*Assumptions!B$53*Assumptions!B$54 | C28: =Assumptions!$B$32*52*C10*Assumptions!C$53*Assumptions!C$54 | D28: =Assumptions!$B$32*52*D10*Assumptions!D$53*Assumptions!D$54 | E28: =Assumptions!$B$32*52*E10*Assumptions!E$53*Assumptions!E$54 | F28: =Assumptions!$B$32*52*F10*Assumptions!F$53*Assumptions!F$54 | G28: =SUM(B28:F28) | H28: hours a week × 52 × outlets × coverage × effectiveness
A29: Staff overhead saved | B29: =B28*Assumptions!$B$10*B8 | C29: =C28*Assumptions!$B$10*C8 | D29: =D28*Assumptions!$B$10*D8 | E29: =E28*Assumptions!$B$10*E8 | F29: =F28*Assumptions!$B$10*F8 | G29: =SUM(B29:F29) | H29: hours × labour cost per hour × wage index
A30: Fresh stock waste avoided | B30: =B12*Assumptions!$B$33*Assumptions!$B$34*Assumptions!B$53*Assumptions!B$54 | C30: =C12*Assumptions!$B$33*Assumptions!$B$34*Assumptions!C$53*Assumptions!C$54 | D30: =D12*Assumptions!$B$33*Assumptions!$B$34*Assumptions!D$53*Assumptions!D$54 | E30: =E12*Assumptions!$B$33*Assumptions!$B$34*Assumptions!E$53*Assumptions!E$54 | F30: =F12*Assumptions!$B$33*Assumptions!$B$34*Assumptions!F$53*Assumptions!F$54 | G30: =SUM(B30:F30) | H30: revenue × waste share × waste avoided
A31: Tea machines avoided | B31: =B10*Assumptions!$B$35*Assumptions!$B$12*12*Assumptions!B$53*Assumptions!B$54 | C31: =C10*Assumptions!$B$35*Assumptions!$B$12*12*Assumptions!C$53*Assumptions!C$54 | D31: =D10*Assumptions!$B$35*Assumptions!$B$12*12*Assumptions!D$53*Assumptions!D$54 | E31: =E10*Assumptions!$B$35*Assumptions!$B$12*12*Assumptions!E$53*Assumptions!E$54 | F31: =F10*Assumptions!$B$35*Assumptions!$B$12*12*Assumptions!F$53*Assumptions!F$54 | G31: =SUM(B31:F31) | H31: net machines avoided × monthly cost × 12
A32: Operating cost savings | B32: =SUM(B29:B31) | C32: =SUM(C29:C31) | D32: =SUM(D29:D31) | E32: =SUM(E29:E31) | F32: =SUM(F29:F31) | G32: =SUM(B32:F32)
A34: TOTAL BENEFIT | B34: =B25+B32 | C34: =C25+C32 | D34: =D25+D32 | E34: =E25+E32 | F34: =F25+F32 | G34: =SUM(B34:F34) | H34: gross profit + cost savings
A36: Additional cost from initiatives
A37: Fixed (one-time)
A38: Project team (manager and AI engineer) | B38: =Assumptions!B$56*(Assumptions!$B$41+Assumptions!$B$42) | C38: =Assumptions!C$56*(Assumptions!$B$41+Assumptions!$B$42) | D38: =Assumptions!D$56*(Assumptions!$B$41+Assumptions!$B$42) | E38: =Assumptions!E$56*(Assumptions!$B$41+Assumptions!$B$42) | F38: =Assumptions!F$56*(Assumptions!$B$41+Assumptions!$B$42) | G38: =SUM(B38:F38) | H38: months × monthly cost; design in 2026, build and pilot in 2027
A39: Platform build | B39: =Assumptions!B$57*Assumptions!$B$43 | C39: =Assumptions!C$57*Assumptions!$B$43 | D39: =Assumptions!D$57*Assumptions!$B$43 | E39: =Assumptions!E$57*Assumptions!$B$43 | F39: =Assumptions!F$57*Assumptions!$B$43 | G39: =SUM(B39:F39) | H39: external developers: app pop-up and delivery-app link; dashboard on off-the-shelf tools
A40: Data pipelines and cloud set-up | B40: =Assumptions!B$57*Assumptions!$B$44 | C40: =Assumptions!C$57*Assumptions!$B$44 | D40: =Assumptions!D$57*Assumptions!$B$44 | E40: =Assumptions!E$57*Assumptions!$B$44 | F40: =Assumptions!F$57*Assumptions!$B$44 | G40: =SUM(B40:F40)
A41: Security and PDPA review | B41: =Assumptions!B$57*Assumptions!$B$45 | C41: =Assumptions!C$57*Assumptions!$B$45 | D41: =Assumptions!D$57*Assumptions!$B$45 | E41: =Assumptions!E$57*Assumptions!$B$45 | F41: =Assumptions!F$57*Assumptions!$B$45 | G41: =SUM(B41:F41) | H41: before customer data drives app pop-ups
A42: Training and cross-training | B42: =Assumptions!B$58*Assumptions!$B$46 | C42: =Assumptions!C$58*Assumptions!$B$46 | D42: =Assumptions!D$58*Assumptions!$B$46 | E42: =Assumptions!E$58*Assumptions!$B$46 | F42: =Assumptions!F$58*Assumptions!$B$46 | G42: =SUM(B42:F42) | H42: by existing zone and store managers: no incremental cost
A43: Total fixed cost | B43: =SUM(B38:B42) | C43: =SUM(C38:C42) | D43: =SUM(D38:D42) | E43: =SUM(E38:E42) | F43: =SUM(F38:F42) | G43: =SUM(B43:F43)
A44: Variable (recurring)
A45: Run team (run and improve the platform) | B45: =Assumptions!B$59*Assumptions!$B$47 | C45: =Assumptions!C$59*Assumptions!$B$47 | D45: =Assumptions!D$59*Assumptions!$B$47 | E45: =Assumptions!E$59*Assumptions!$B$47 | F45: =Assumptions!F$59*Assumptions!$B$47 | G45: =SUM(B45:F45) | H45: from 2028
A46: Software maintenance | B46: =Assumptions!B$59*Assumptions!$B$49*Assumptions!$B$43 | C46: =Assumptions!C$59*Assumptions!$B$49*Assumptions!$B$43 | D46: =Assumptions!D$59*Assumptions!$B$49*Assumptions!$B$43 | E46: =Assumptions!E$59*Assumptions!$B$49*Assumptions!$B$43 | F46: =Assumptions!F$59*Assumptions!$B$49*Assumptions!$B$43 | G46: =SUM(B46:F46) | H46: share of the platform build a year, from 2028
A47: Cloud, licences and AI services | B47: =Assumptions!B$60*Assumptions!$B$48 | C47: =Assumptions!C$60*Assumptions!$B$48 | D47: =Assumptions!D$60*Assumptions!$B$48 | E47: =Assumptions!E$60*Assumptions!$B$48 | F47: =Assumptions!F$60*Assumptions!$B$48 | G47: =SUM(B47:F47) | H47: half a year in 2027
...

Sheet SG forecast
A1: Chagee Singapore · five-year forecast with the three proposals (S$)
A2: Outlet level, before head-office costs and new-store set-up (capex). Illustrative assumptions, not Chagee data.
A4: S$ | B4: 2026 | C4: 2027 | D4: 2028 | E4: 2029 | F4: 2030 | G4: 5-year total | H4: Notes
A6: Scale
A7: Outlets at year end | B7: =Assumptions!$B$5+SUM(Assumptions!$B$55:B$55) | C7: =Assumptions!$B$5+SUM(Assumptions!$B$55:C$55) | D7: =Assumptions!$B$5+SUM(Assumptions!$B$55:D$55) | E7: =Assumptions!$B$5+SUM(Assumptions!$B$55:E$55) | F7: =Assumptions!$B$5+SUM(Assumptions!$B$55:F$55) | H7: today's outlets + new outlets
A8: Cups sold | B8: =Model!B11+Model!B18 | C8: =Model!C11+Model!C18 | D8: =Model!D11+Model!D18 | E8: =Model!E11+Model!E18 | F8: =Model!F11+Model!F18 | G8: =SUM(B8:F8) | H8: baseline + extra cups from the proposals
A10: Revenue
A11: Baseline sales (organic growth and new outlets) | B11: =Model!B12 | C11: =Model!C12 | D11: =Model!D12 | E11: =Model!E12 | F11: =Model!F12 | G11: =SUM(B11:F11) | H11: Model sheet
A12: Additional sales from the proposals | B12: =Model!B23 | C12: =Model!C23 | D12: =Model!D23 | E12: =Model!E23 | F12: =Model!F23 | G12: =SUM(B12:F12) | H12: Model sheet
A13: Total revenue | B13: =B11+B12 | C13: =C11+C12 | D13: =D11+D12 | E13: =E11+E12 | F13: =F11+F12 | G13: =SUM(B13:F13)
A14: Cost of goods sold | B14: =-B13*(1-Assumptions!$B$8)+Model!B30 | C14: =-C13*(1-Assumptions!$B$8)+Model!C30 | D14: =-D13*(1-Assumptions!$B$8)+Model!D30 | E14: =-E13*(1-Assumptions!$B$8)+Model!E30 | F14: =-F13*(1-Assumptions!$B$8)+Model!F30 | G14: =SUM(B14:F14) | H14: revenue × (1 − gross margin), less fresh-stock waste avoided (Proposal 2)
A15: Gross profit | B15: =B13+B14 | C15: =C13+C14 | D15: =D13+D14 | E15: =E13+E14 | F15: =F13+F14 | G15: =SUM(B15:F15)
A16: Gross margin | B16: =IF(B13=0,0,B15/B13) | C16: =IF(C13=0,0,C15/C13) | D16: =IF(D13=0,0,D15/D13) | E16: =IF(E13=0,0,E15/E13) | F16: =IF(F13=0,0,F15/F13)
A18: Operating expenses
A19: Staff | B19: =-Model!B10*Assumptions!$B$15*Assumptions!$B$16*Assumptions!$B$17*Assumptions!$B$10*Model!B8+Model!B29 | C19: =-Model!C10*Assumptions!$B$15*Assumptions!$B$16*Assumptions!$B$17*Assumptions!$B$10*Model!C8+Model!C29 | D19: =-Model!D10*Assumptions!$B$15*Assumptions!$B$16*Assumptions!$B$17*Assumptions!$B$10*Model!D8+Model!D29 | E19: =-Model!E10*Assumptions!$B$15*Assumptions!$B$16*Assumptions!$B$17*Assumptions!$B$10*Model!E8+Model!E29 | F19: =-Model!F10*Assumptions!$B$15*Assumptions!$B$16*Assumptions!$B$17*Assumptions!$B$10*Model!F8+Model!F29 | G19: =SUM(B19:F19) | H19: outlets × staff on shift × hours × days × wage × wage index, less idle hours saved (Proposal 2)
A20: Rent and utilities | B20: =-Model!B10*(Assumptions!$B$18+Assumptions!$B$19)*12 | C20: =-Model!C10*(Assumptions!$B$18+Assumptions!$B$19)*12 | D20: =-Model!D10*(Assumptions!$B$18+Assumptions!$B$19)*12 | E20: =-Model!E10*(Assumptions!$B$18+Assumptions!$B$19)*12 | F20: =-Model!F10*(Assumptions!$B$18+Assumptions!$B$19)*12 | G20: =SUM(B20:F20) | H20: outlets × monthly cost × 12
A21: Delivery-app commissions | B21: =-B11*Assumptions!$B$20*Assumptions!$B$21 | C21: =-C11*Assumptions!$B$20*Assumptions!$B$21 | D21: =-D11*Assumptions!$B$20*Assumptions!$B$21 | E21: =-E11*Assumptions!$B$20*Assumptions!$B$21 | F21: =-F11*Assumptions!$B$20*Assumptions!$B$21 | G21: =SUM(B21:F21) | H21: baseline revenue × delivery share × commission
A22: Equipment: tea machines avoided | B22: =Model!B31 | C22: =Model!C31 | D22: =Model!D31 | E22: =Model!E31 | F22: =Model!F31 | G22: =SUM(B22:F22) | H22: Proposal 2, Model sheet
A23: AI platform and team | B23: =-Model!B52 | C23: =-Model!C52 | D23: =-Model!D52 | E23: =-Model!E52 | F23: =-Model!F52 | G23: =SUM(B23:F23) | H23: cost of the initiatives, Model sheet
A24: Total operating expenses | B24: =SUM(B19:B23) | C24: =SUM(C19:C23) | D24: =SUM(D19:D23) | E24: =SUM(E19:E23) | F24: =SUM(F19:F23) | G24: =SUM(B24:F24)
A26: OUTLET OPERATING PROFIT (before head-office costs) | B26: =B15+B24 | C26: =C15+C24 | D26: =D15+D24 | E26: =E15+E24 | F26: =F15+F24 | G26: =SUM(B26:F26)
A27: Operating margin | B27: =IF(B13=0,0,B26/B13) | C27: =IF(C13=0,0,C26/C13) | D27: =IF(D13=0,0,D26/D13) | E27: =IF(E13=0,0,E26/E13) | F27: =IF(F13=0,0,F26/F13)
A29: Memo: without the proposals
A30: Outlet operating profit without the proposals | B30: =B11*Assumptions!$B$8-Model!B10*Assumptions!$B$15*Assumptions!$B$16*Assumptions!$B$17*Assumptions!$B$10*Model!B8+B20+B21 | C30: =C11*Assumptions!$B$8-Model!C10*Assumptions!$B$15*Assumptions!$B$16*Assumptions!$B$17*Assumptions!$B$10*Model!C8+C20+C21 | D30: =D11*Assumptions!$B$8-Model!D10*Assumptions!$B$15*Assumptions!$B$16*Assumptions!$B$17*Assumptions!$B$10*Model!D8+D20+D21 | E30: =E11*Assumptions!$B$8-Model!E10*Assumptions!$B$15*Assumptions!$B$16*Assumptions!$B$17*Assumptions!$B$10*Model!E8+E20+E21 | F30: =F11*Assumptions!$B$8-Model!F10*Assumptions!$B$15*Assumptions!$B$16*Assumptions!$B$17*Assumptions!$B$10*Model!F8+F20+F21 | G30: =SUM(B30:F30) | H30: baseline gross profit − staff − rent and utilities − delivery commissions
A31: Operating margin without the proposals | B31: =IF(B11=0,0,B30/B11) | C31: =IF(C11=0,0,C30/C11) | D31: =IF(D11=0,0,D30/D11) | E31: =IF(E11=0,0,E30/E11) | F31: =IF(F11=0,0,F30/F11)
A32: Uplift from the proposals | B32: =B26-B30 | C32: =C26-C30 | D32: =D26-D30 | E32: =E26-E30 | F32: =F26-F30 | G32: =SUM(B32:F32) | H32: equals the Model sheet's net impact

Sheet Cost plan
A1: Cost of the initiatives by stage (S$)
A2: Linked to the Assumptions sheet. Fixed costs are one-time; recurring costs are per year at full scale.
A4: Stage | B4: Timing | C4: Task | D4: Resources | E4: Fixed, one-time | F4: Recurring, per year
A5: Design and plan | B5: Oct–Dec 2026 | C5: Design the three proposals, audit data, plan the pilots | D5: Project manager, AI engineer | E5: =Assumptions!B$56*(Assumptions!$B$41+Assumptions!$B$42)
A6: Build and pilot | B6: 2027 | C6: Build the platform: app pop-up and delivery-app link; configure the dashboard and assistant on off-the-shelf tools | D6: External developers | E6: =Assumptions!$B$43
B7: 2027 | C7: Data pipelines and cloud set-up | D7: AI engineer | E7: =Assumptions!$B$44
B8: 2027 | C8: Security testing and PDPA review | D8: External specialist | E8: =Assumptions!$B$45
B9: 2027 | C9: Run the project: pilots, go/no-go, roll-out | D9: Project manager, AI engineer | E9: =Assumptions!C$56*(Assumptions!$B$41+Assumptions!$B$42)
B10: 2027 | C10: Train and cross-train outlet teams | D10: Zone and store managers (existing staff) | E10: =Assumptions!C$58*Assumptions!$B$46
A11: Run and scale | B11: 2028 onwards | C11: Run and improve the platform | D11: Run team | F11: =Assumptions!$B$47
B12: 2028 onwards | C12: Maintain the externally built software | D12: External developers | F12: =Assumptions!$B$49*Assumptions!$B$43
B13: 2028 onwards | C13: Cloud, licences and AI services | D13: Cloud provider | F13: =Assumptions!$B$48
B14: 2028 onwards | C14: Chagee managers' time | D14: Supply chain, zone and store managers (existing staff) | F14: =Assumptions!D$61
B15: 2028 onwards | C15: Switch perks for redirected customers | D15: Proposal 1 | F15: =Model!F49
B16: 2028 onwards | C16: Train each new outlet | D16: Store manager (existing staff) | F16: =Assumptions!D$58*Assumptions!$B$46
A17: Total | E17: =SUM(E5:E16) | F17: =SUM(F5:F16)
